Workbook

Sheet Spinning
A1: Location | B1: Business | C1: Section | D1: Sr_No | E1: Dept_Machine_Name | F1: Designation | G1: Machine_Count | H1: Workload | I1: Formulas | J1: BE_Scientific_Manpower | K1: Operator_Type | L1: Contractors | M1: Company_Associate | N1: BE_Final_Manpower | O1: General_Shift | P1: Shift_A | Q1: Shift_B | R1: Shift_C | S1: Reliever | T1: Remarks
A2: Vapi | B2: Spinning | C2: PREPARATORY | D2: 1 | E2: Blow Room (Incl. line 7 & 8) | F2: BLOW ROOM OPERATOR | G2: 8 | H2: 1 Person/2 Lines | I2: (8/2)*3 | J2: 12 | N2: 9 | O2: 0 | P2: 3 | Q2: 3 | R2: 3 | S2: 0 | T2: Based on utilation of workload we given total 9
A3: Vapi | B3: Spinning | C3: PREPARATORY | D3: 2 | E3: Carding Ring Spinning | F3: Operator | G3: 52 | H3: 22 cards/opt | I3: (52/22)*3 | J3: 7.09 | N3: 9 | O3: 0 | P3: 3 | Q3: 3 | R3: 3 | S3: 0
A4: Vapi | B4: Spinning | C4: PREPARATORY | D4: 3 | E4: Carding Open End | F4: Operator | G4: 9 | H4: 9 cards | I4: (9/9)*3 | J4: 3 | N4: 3 | O4: 0 | P4: 1 | Q4: 1 | R4: 1 | S4: 0
A5: Vapi | B5: Spinning | C5: PREPARATORY | D5: 4 | E5: Breaker Draw Frames | F5: Operator | G5: 22 | H5: 4 del/opt | I5: (22/4)*3 | J5: 16.5 | N5: 18 | O5: 0 | P5: 6 | Q5: 6 | R5: 6 | S5: 0
A6: Vapi | B6: Spinning | C6: PREPARATORY | D6: 5 | E6: Levelling Del | F6: Operator | G6: 4 | H6: 4 del/opt | I6: (4/4)*3 | J6: 3 | N6: 3 | O6: 0 | P6: 1 | Q6: 1 | R6: 1 | S6: 0
A7: Vapi | B7: Spinning | C7: PREPARATORY | D7: 6 | E7: Unilap | F7: Operator | G7: 3 | H7: 2 machine/person | I7: (3/2)*3 | J7: 4.5 | N7: 6 | O7: 0 | P7: 2 | Q7: 2 | R7: 2 | S7: 0
A8: Vapi | B8: Spinning | C8: PREPARATORY | D8: 7 | E8: Combers | F8: Operator | G8: 18 | H8: 10 Combers/Opt | I8: (18/10)*3 | J8: 5.4 | N8: 6 | O8: 0 | P8: 2 | Q8: 2 | R8: 2 | S8: 0
A9: Vapi | B9: Spinning | C9: PREPARATORY | D9: 8 | E9: Finisher Draw Frames | F9: Operator | G9: 21 | H9: 4 del/opt | I9: (21/4)*3 | J9: 15.75 | N9: 15 | O9: 0 | P9: 5 | Q9: 5 | R9: 5 | S9: 0
A10: Vapi | B10: Spinning | C10: PREPARATORY | D10: 9 | E10: Open End Finisher Draw Frames | F10: Operator | G10: 5 | H10: 4 del/opt | I10: (5/4)*3 | J10: 3.75 | N10: 4 | O10: 1 | P10: 1 | Q10: 1 | R10: 1 | S10: 0
A11: Vapi | B11: Spinning | C11: PREPARATORY | D11: 10 | E11: Speed Frames | F11: Operator | G11: 16 | H11: 2 Machine/opt | I11: (16/2)*3 | J11: 24 | N11: 27 | O11: 0 | P11: 9 | Q11: 9 | R11: 9 | S11: 0 | T11: this number may change after final trials
A12: Vapi | B12: Spinning | C12: PREPARATORY | D12: 11 | E12: S.F Doffing | F12: Doffer | G12: 16 | H12: 1250 Bobbins/doffer/shift | I12: (16/2)*3 | J12: 24 | N12: 27 | O12: 0 | P12: 9 | Q12: 9 | R12: 9 | S12: 0
A13: Vapi | B13: Spinning | C13: PREPARATORY | D13: 12 | E13: Can Transporter | F13: Material Handler | H13: transportation of cans from carding to finisher D/F | I13: 1*3 | J13: 3 | N13: 3 | O13: 3 | P13: 0 | Q13: 0 | R13: 0 | S13: 0
A14: Vapi | B14: Spinning | C14: PREPARATORY | D14: 13 | E14: Jobber | F14: Jobber | H14: Monitor/Jobber | I14: 2*3 | J14: 6 | N14: 6 | O14: 0 | P14: 2 | Q14: 2 | R14: 2 | S14: 0
A15: Vapi | B15: Spinning | C15: PREPARATORY | D15: 14 | E15: House Keeping | F15: House Keeper | H15: Contractors | I15: 2*3 | J15: 6 | N15: 6 | O15: 0 | P15: 2 | Q15: 2 | R15: 2 | S15: 0
A16: Vapi | B16: Spinning | C16: PREPARATORY | D16: 15 | E16: Reliever | F16: Operator | H16: 18.75 persons to be relieved (D/F/unilap/Combers) | I16: 0*3 | J16: 0 | N16: 0 | O16: 0 | P16: 0 | Q16: 0 | R16: 0 | S16: 0 | T16: Don't need a reliever.
A17: Vapi | B17: Spinning | C17: RING FRAME | D17: 1 | E17: R/F Operators (7 LR) | F17: Operator | G17: 7 | H17: 1000 Spdls/ opt | I17: ROUND((7*1440)/1000,0)*3 | J17: 30 | N17: 30 | O17: 0 | P17: 10 | Q17: 10 | R17: 10 | S17: 0
A18: Vapi | B18: Spinning | C18: RING FRAME | D18: 2 | E18: R/F Operators (12 Toyota) | F18: Operator | G18: 12 | H18: 1440 Spdls/ opt | I18: ROUND(((12*1008)/1440)*3,0) | J18: 25 | N18: 25 | O18: 0 | P18: 8 | Q18: 8 | R18: 8 | S18: 0
A19: Vapi | B19: Spinning | C19: RING FRAME | D19: 3 | E19: R/F Operators (18 LR) | F19: Operator | G19: 18 | H19: 1440 Spdls/ opt | I19: ROUND(((18*1440)/1440)*3,0) | J19: 54 | N19: 54 | O19: 0 | P19: 18 | Q19: 18 | R19: 18 | S19: 0
A20: Vapi | B20: Spinning | C20: RING FRAME | D20: 4 | E20: R/F Operators (4 Toyota) | F20: Operator | G20: 4 | H20: 1100 Spdls/ opt | I20: ROUND(((4*1104)/1104)*3,0) | J20: 12 | N20: 12 | O20: 0 | P20: 4 | Q20: 4 | R20: 4 | S20: 0
A21: Vapi | B21: Spinning | C21: RING FRAME | D21: 5 | E21: R/F Relievers | F21: Operator | H21: 15% of operators | I21: ROUND(SUM(K17:K20)*15%,0) | J21: 18 | N21: 18 | O21: 0 | P21: 6 | Q21: 6 | R21: 6 | S21: 0
A22: Vapi | B22: Spinning | C22: RING FRAME | D22: 6 | E22: Bobbin Changer | F22: Operator | H22: 850 bobbins/opt | I22: (7+12+18+4) | J22: 41 | N22: 41 | O22: 0 | P22: 14 | Q22: 14 | R22: 13 | S22: 0
A23: Vapi | B23: Spinning | C23: RING FRAME | D23: 7 | E23: Doffer gaitors (7 LR) | F23: Operator | G23: 7 | H23: 46 Doffs | I23: ROUND((46/30),0)*3 | J23: 6 | N23: 6 | O23: 0 | P23: 2 | Q23: 2 | R23: 2 | S23: 0
A24: Vapi | B24: Spinning | C24: RING FRAME | D24: 8 | E24: Doffer gaitors (12 Toyota) | F24: Operator | G24: 12 | H24: 61 Doffs | I24: ROUND((61/30),0)*3 | J24: 6 | N24: 6 | O24: 0 | P24: 2 | Q24: 2 | R24: 2 | S24: 0
A25: Vapi | B25: Spinning | C25: RING FRAME | D25: 9 | E25: Doffer gaitors (18 LR) | F25: Operator | G25: 18 | H25: 107 Doffs | I25: ROUND((107/30),0)*3 | J25: 12 | N25: 12 | O25: 0 | P25: 4 | Q25: 4 | R25: 4 | S25: 0
A26: Vapi | B26: Spinning | C26: RING FRAME | D26: 10 | E26: Doffer gaitors (4 Toyota) | F26: Operator | G26: 4 | H26: 22 Doffs | I26: ROUND((22/25),0)*3 | J26: 3 | N26: 3 | O26: 0 | P26: 1 | Q26: 1 | R26: 1 | S26: 0
A27: Vapi | B27: Spinning | C27: RING FRAME | D27: 11 | E27: Jobber | F27: Jobber/Monitor | I27: 3*3 | J27: 9 | N27: 9 | O27: 0 | P27: 3 | Q27: 3 | R27: 3 | S27: 0 | T27: Ok
A28: Vapi | B28: Spinning | C28: RING FRAME | D28: 12 | E28: BTS Operator | F28: Operator | I28: 2*3 | J28: 6 | N28: 6 | O28: 0 | P28: 2 | Q28: 2 | R28: 2 | S28: 0 | T28: Ok
A29: Vapi | B29: Spinning | C29: RING FRAME | D29: 13 | E29: Tube Loader for 12 Toyota | F29: Tube loader | I29: 2*3 | J29: 6 | N29: 6 | O29: 0 | P29: 2 | Q29: 2 | R29: 2 | S29: 0 | T29: Need to check
A30: Vapi | B30: Spinning | C30: RING FRAME | D30: 14 | E30: Bobbin Stripper | F30: Contractors | I30: 2*3 | J30: 6 | N30: 6 | O30: 0 | P30: 2 | Q30: 2 | R30: 2 | S30: 0 | T30: Need to check
A31: Vapi | B31: Spinning | C31: RING FRAME | D31: 15 | E31: House Keeper | F31: Contractors | I31: 2*3 | J31: 6 | N31: 6 | O31: 0 | P31: 2 | Q31: 2 | R31: 2 | S31: 0 | T31: Ok
A32: Vapi | B32: Spinning | C32: RING FRAME | D32: 16 | E32: R/F Cleaning | H32: 2 hrs machine downtime | I32: 2*3 | J32: 6 | N32: 6 | O32: 0 | P32: 2 | Q32: 2 | R32: 2 | S32: 0 | T32: Ok
A33: Vapi | B33: Spinning | C33: RING FRAME | D33: 17 | E33: Traveller Change | H33: 15 min/machine | I33: 2*3 | J33: 6 | N33: 6 | O33: 0 | P33: 2 | Q33: 2 | R33: 2 | S33: 0 | T33: Ok
A34: Vapi | B34: Spinning | C34: RING FRAME | D34: 18 | E34: Lot Change | H34: 2 hrs/machine | I34: 2*3 | J34: 6 | N34: 6 | O34: 0 | P34: 2 | Q34: 2 | R34: 2 | S34: 0 | T34: Ok
A35: Vapi | B35: Spinning | C35: RING FRAME | D35: 19 | E35: Draft zone Cleaning | F35: Contractors | I35: 4*3 | J35: 12 | N35: 12 | O35: 0 | P35: 4 | Q35: 4 | R35: 4 | S35: 0
A36: Vapi | B36: Spinning | C36: AUTOCONER | D36: 1 | E36: Link Coner operator | G36: 29 | H36: 4 Machines/Opt | I36: ROUND((29/4)*3,0) | J36: 22 | N36: 21 | O36: 0 | P36: 7 | Q36: 7 | R36: 7 | S36: 0
A37: Vapi | B37: Spinning | C37: AUTOCONER | D37: 2 | E37: Autoconer Operators | G37: 6 | H37: 30 drums/opt total = (300 Drums) | I37: ROUND((300/30)*3,0) | J37: 30 | N37: 30 | O37: 0 | P37: 10 | Q37: 10 | R37: 10 | S37: 0
A38: Vapi | B38: Spinning | C38: AUTOCONER | D38: 3 | E38: Cone carrier | I38: 2*3 | J38: 6 | N38: 6 | O38: 0 | P38: 2 | Q38: 2 | R38: 2 | S38: 0 | T38: Ok
A39: Vapi | B39: Spinning | C39: AUTOCONER | D39: 4 | E39: Reliever | I39: 2*3 | J39: 6 | N39: 6 | O39: 0 | P39: 2 | Q39: 2 | R39: 2 | S39: 0 | T39: Ok
A40: Vapi | B40: Spinning | C40: AUTOCONER | D40: 5 | E40: Jobber | F40: Jobber/Monitor | I40: 1*3 | J40: 3 | N40: 3 | O40: 0 | P40: 1 | Q40: 1 | R40: 1 | S40: 0 | T40: Ok
...

Sheet TFO
A1: Count | B1: Customer | C1: Count2 | D1: Speed | E1: TPI | F1: Utilization | G1: Efficiency | H1: Formula_Production per Drum/ day | I1: Production per Drum/ day | J1: formula_Production Required / Month Kgs | K1: Production Required / Month Kgs | L1: Production Required / day Kgs | M1: formul_No. of Drums Required | N1: No. of Drums Required | O1: formula_No. of TFO Required/ shift | P1: No. of TFO Required/ shift | Q1: mpm | R1: Eff | S1: Formula_kgs/drum/day | T1: kgs/drum/day | U1: formula_No. of Drums | V1: No. of Drums | W1: formula_no. of machines | X1: no. of machines
A2: 2/24 KW | B2: Vapi | C2: 12 | D2: 9000 | E2: 8.5 | F2: 0.98 | G2: 0.88 | H2: ((D2*60*8*G2*2)/(E2*36*840*C2*2.202))*3 | I2: =((D2*60*8*G2*2)/(E2*36*840*C2*2.202))*3 -> 3.3582915 | J2: L2*30 | K2: =L2*30 -> 281594.88 | L2: 9386.496 | M2: L2/I2 | N2: =L2/I2 -> 2795.0212 | O2: No. of Drums Required/240 | P2: =N2/240 -> 11.645922 | Q2: 850 | R2: 0.85 | S2: Q2*R2*8*60*1.09/(C2*840*2.202)*3 | T2: =Q2*R2*8*60*1.09/(C2*840*2.202)*3 -> 51.09154 | U2: (Production Required / day Kgs )/kgs/drum/day | V2: =L2/T2 -> 183.71918 | W2: V2/72 | X2: =V2/72 -> 2.5516553
A3: 2/24 KW | B3: Vapi | C3: 12 | D3: 6000 | E3: 8.5 | F3: 0.97 | G3: 0.85 | I3: =((D3*60*8*G3*2)/(E3*36*840*C3*2.202))*3 -> 2.1625362 | K3: =L3*30 -> 0 | L3: 0 | N3: =L3/I3 -> 0 | O3: No. of Drums Required/240 | P3: =N3/240 -> 0 | T3: =Q3*R3*8*60*1.09/(C3*840*2.202)*3 -> 0 | V3: 0 | X3: =V3/72 -> 0
A4: 2/30 CW bci Anjar | B4: Anjar | C4: 15 | D4: 10000 | E4: 11 | F4: 0.98 | G4: 0.9 | I4: =((D4*60*8*G4*2)/(E4*36*840*C4*2.202))*3 -> 2.3591304 | K4: =L4*30 -> 42240 | L4: 1408 | N4: =L4/I4 -> 596.83008 | O4: No. of Drums Required/240 | P4: =N4/240 -> 2.486792 | Q4: 950 | R4: 0.85 | T4: =Q4*R4*8*60*1.09/(C4*840*2.202)*3 -> 45.681848 | V4: =L4/T4 -> 30.821871 | X4: =V4/72 -> 0.42808154
A5: 2/20 KW | B5: Vapi | C5: 10 | D5: 8500 | E5: 8.5 | F5: 0.98 | G5: 0.87 | I5: =((D5*60*8*G5*2)/(E5*36*840*C5*2.202))*3 -> 3.762813 | K5: =L5*30 -> 359040 | L5: 11968 | N5: =L5/I5 -> 3180.5992 | O5: No. of Drums Required/240 | P5: =N5/240 -> 13.252497 | Q5: 850 | R5: 0.85 | T5: =Q5*R5*8*60*1.09/(C5*840*2.202)*3 -> 61.309848 | V5: =L5/T5 -> 195.20518 | X5: =V5/72 -> 2.7111831
A6: 2/20 KW BCI Anjar | B6: Anjar | C6: 10 | D6: 7000 | E6: 8.5 | F6: 0.98 | G6: 0.87 | I6: =((D6*60*8*G6*2)/(E6*36*840*C6*2.202))*3 -> 3.0987872 | K6: =L6*30 -> 0 | L6: 0 | N6: =L6/I6 -> 0 | O6: No. of Drums Required/240 | P6: =N6/240 -> 0 | Q6: 850 | R6: 0.85 | T6: =Q6*R6*8*60*1.09/(C6*840*2.202)*3 -> 61.309848 | V6: =L6/T6 -> 0 | X6: =V6/72 -> 0
A7: 2/12 K bci Anjar | B7: Anjar | C7: 6 | D7: 6000 | E7: 6.5 | F7: 0.98 | G7: 0.8 | I7: =((D7*60*8*G7*2)/(E7*36*840*C7*2.202))*3 -> 5.3231661 | K7: =L7*30 -> 39454.228 | L7: 1315.1409 | N7: =L7/I7 -> 247.05991 | O7: No. of Drums Required/240 | P7: =N7/240 -> 1.0294163 | Q7: 800 | R7: 0.85 | T7: =Q7*R7*8*60*1.09/(C7*840*2.202)*3 -> 96.172311 | V7: =L7/T7 -> 13.67484 | X7: =V7/72 -> 0.18992833
A8: 2/9 KC | B8: Vapi | C8: 4.5 | D8: 4000 | E8: 6.5 | F8: 0.98 | G8: 0.75 | I8: =((D8*60*8*G8*2)/(E8*36*840*C8*2.202))*3 -> 4.4359717 | K8: =L8*30 -> 99030 | L8: 3301 | N8: =L8/I8 -> 744.1436 | O8: No. of Drums Required/240 | P8: =N8/240 -> 3.1005984 | Q8: 700 | R8: 0.85 | T8: =Q8*R8*8*60*1.09/(C8*840*2.202)*3 -> 112.20103 | V8: =L8/T8 -> 29.420407 | X8: =V8/72 -> 0.40861677
A9: 2/6 kc | B9: Rugs | C9: 3 | D9: 4000 | E9: 6.5 | F9: 0.98 | G9: 0.8 | I9: =((D9*60*8*G9*2)/(E9*36*840*C9*2.202))*3 -> 7.0975548 | K9: =L9*30 -> 0 | L9: 0 | N9: =L9/I9 -> 0 | O9: No. of Drums Required/240 | P9: =N9/240 -> 0 | Q9: 850 | R9: 0.85 | T9: =Q9*R9*8*60*1.09/(C9*840*2.202)*3 -> 204.36616 | V9: =L9/T9 -> 0 | X9: =V9/72 -> 0
A10: 2/6 kc | B10: Rugs | C10: 3 | D10: 3500 | E10: 6.5 | F10: 0.98 | G10: 0.8 | I10: =((D10*60*8*G10*2)/(E10*36*840*C10*2.202))*3 -> 6.2103604 | K10: =L10*30 -> 0 | L10: 0 | N10: =L10/I10 -> 0 | O10: No. of Drums Required/240 | P10: =N10/240 -> 0 | Q10: 850 | R10: 0.85 | T10: =Q10*R10*8*60*1.09/(C10*840*2.202)*3 -> 204.36616 | V10: =L10/T10 -> 0 | X10: =V10/72 -> 0
A11: 2/19 C hygro | B11: Vapi | C11: 9.5 | D11: 6000 | E11: 6.5 | F11: 0.98 | G11: 0.85 | I11: =((D11*60*8*G11*2)/(E11*36*840*C11*2.202))*3 -> 3.5721246 | K11: =L11*30 -> 0 | L11: 0 | N11: =L11/I11 -> 0 | O11: No. of Drums Required/240 | P11: =N11/240 -> 0 | Q11: 850 | R11: 0.85 | T11: =Q11*R11*8*60*1.09/(C11*840*2.202)*3 -> 64.536682 | V11: =L11/T11 -> 0 | X11: =V11/72 -> 0
A12: 9 com +80 PVA | B12: Vapi | C12: 8.0898876 | D12: 7000 | E12: 13 | F12: 0.98 | G12: 0.85 | I12: =((D12*60*8*G12*2)/(E12*36*840*C12*2.202))*3 -> 2.4469467 | K12: =L12*30 -> 0 | L12: 0 | N12: =L12/I12 -> 0 | O12: No. of Drums Required/240 | P12: =N12/240 -> 0 | Q12: 700 | R12: 0.85 | T12: =Q12*R12*8*60*1.09/(C12*840*2.202)*3 -> 62.411823 | V12: =L12/T12 -> 0 | X12: =V12/72 -> 0
A13: DYED/ Others OS | B13: Vapi | C13: 13.333333 | D13: 8000 | E13: 15 | F13: 0.98 | G13: 0.85 | I13: =((D13*60*8*G13*2)/(E13*36*840*C13*2.202))*3 -> 1.4705246 | K13: =L13*30 -> 69690 | L13: 2323 | N13: =L13/I13 -> 1579.7083 | O13: No. of Drums Required/240 | P13: =N13/240 -> 6.582118 | Q13: 850 | R13: 0.85 | T13: =Q13*R13*8*60*1.09/(C13*840*2.202)*3 -> 45.982386 | V13: =L13/T13 -> 50.519344 | X13: =V13/72 -> 0.70165756
A14: 16+106 80 PVA OS | B14: Vapi | C14: 13.333333 | D14: 8000 | E14: 19 | F14: 0.98 | G14: 0.9 | I14: =((D14*60*8*G14*2)/(E14*36*840*C14*2.202))*3 -> 1.2292311 | K14: =L14*30 -> 128610 | L14: 4287 | N14: =L14/I14 -> 3487.546 | O14: No. of Drums Required/240 | P14: =N14/240 -> 14.531441 | Q14: 850 | R14: 0.85 | T14: =Q14*R14*8*60*1.09/(C14*840*2.202)*3 -> 45.982386 | V14: =L14/T14 -> 93.231351 | X14: =V14/72 -> 1.2948799
A15: 13 hygro+80 PVA | B15: Vapi | C15: 11.182796 | D15: 8500 | E15: 13 | F15: 0.98 | G15: 0.9 | I15: =((D15*60*8*G15*2)/(E15*36*840*C15*2.202))*3 -> 2.2759414 | K15: =L15*30 -> 91530 | L15: 3051 | N15: =L15/I15 -> 1340.5442 | O15: No. of Drums Required/240 | P15: =N15/240 -> 5.5856007 | Q15: 850 | R15: 0.85 | T15: =Q15*R15*8*60*1.09/(C15*840*2.202)*3 -> 54.825153 | V15: =L15/T15 -> 55.64964 | X15: =V15/72 -> 0.77291166
... A18: 13 CC +80 PVA OS | B18: Vapi | C18: 11.182796 | D18: 7000 | E18: 13 | F18: 0.98 | G18: 0.9 | I18: =((D18*60*8*G18*2)/(E18*36*840*C18*2.202))*3 -> 1.8743047 | K18: =L18*30 -> 0 | L18: 0 | N18: =L18/I18 -> 0 | O18: No. of Drums Required/240 | P18: =N18/240 -> 0 | Q18: 850 | R18: 0.85 | T18: =Q18*R18*8*60*1.09/(C18*840*2.202)*3 -> 54.825153 | V18: =L18/T18 -> 0 | X18: =V18/72 -> 0
A19: 4/2/6 K | B19: Rugs | C19: 0.75 | D19: 2000 | E19: 2.8 | F19: 0.98 | G19: 0.7 | I19: =((D19*60*8*G19*2)/(E19*36*840*C19*2.202))*3 -> 28.833816 | K19: =L19*30 -> 81413.486 | L19: 2713.7829 | M19: L19/I19 | N19: =L19/I19 -> 94.11806 | O19: No. of Drums Required/80 | P19: =N19/80 -> 1.1764758 | Q19: 400 | R19: 0.7 | T19: =Q19*R19*8*60*1.09/(C19*840*2.202)*3 -> 316.80291 | V19: =L19/T19 -> 8.5661552 | X19: =V19/72 -> 0.11897438
A22: Location | B22: Business | C22: Section | D22: Sr_No | E22: Dept_Machine_Name | F22: Designation | G22: Machine_Count | H22: Workload | I22: Formulas | J22: BE_Scientific_Manpower | K22: BE_Final_Manpower | L22: General_Shift | M22: Shift_A | N22: Shift_B | O22: Shift_C | P22: Reliever | Q22: Remarks
A23: Vapi | B23: Spinning | C23: TFO | D23: 1 | E23: Assembly winding | F23: operator | I23: ROUNDUP((((SUM(T2:T18)/36)+(T19/36))*3),0) | J23: 62 | K23: =J23 -> 62 | L23: 0 | M23: 21 | N23: 21 | O23: 20 | P23: 0
A24: Vapi | B24: Spinning | C24: TFO | D24: 2 | E24: Jumbo Assembly Winding | F24: operator | I24: ROUND(ROUNDUP(T19,0)/16,0)*2 | J24: 2 | K24: =J24 -> 2 | L24: 0 | M24: 1 | N24: 1 | O24: 0 | P24: 0
A25: Vapi | B25: Spinning | C25: TFO | D25: 3 | E25: TFO | F25: TFO Operator | I25: ROUND(+SUM(N2:N18)/6,0)*3 | J25: 33 | K25: =J25 -> 33 | L25: 0 | M25: 12 | N25: 12 | O25: 12 | P25: 0
A26: Vapi | B26: Spinning | C26: TFO | D26: 4 | E26: TFO | F26: TFO Operator (Doffer) | I26: ROUNDUP(+SUM(N2:N18)/4,0)*3 | J26: 51 | K26: =J26 -> 51 | L26: 0 | M26: 17 | N26: 17 | O26: 17 | P26: 0
A27: Vapi | B27: Spinning | C27: TFO | D27: 5 | E27: Jumbo TFO | F27: TFO Operator | I27: 2*3 | J27: 6 | K27: =J27 -> 6 | L27: 0 | M27: 2 | N27: 2 | O27: 2 | P27: 0
A28: Vapi | B28: Spinning | C28: TFO | D28: 6 | E28: Vijaylakshmi TFO | F28: TFO Operator | I28: 2*3 | J28: 6 | K28: =J28 -> 6 | L28: 0 | M28: 2 | N28: 2 | O28: 2 | P28: 0
A29: Vapi | B29: Spinning | C29: TFO | D29: 7 | E29: Jobber | F29: Jobber | I29: 1*3 | J29: 3 | K29: =J29 -> 3 | L29: 0 | M29: 1 | N29: 1 | O29: 1 | P29: 0
A30: Vapi | B30: Spinning | C30: TFO | D30: 8 | E30: Cone Carrier | F30: Cone carrier | I30: 1*3 | J30: 3 | K30: =J30 -> 3 | L30: 0 | M30: 1 | N30: 1 | O30: 1 | P30: 0
A31: Vapi | B31: Spinning | C31: TFO | D31: 9 | E31: Cone Checker | F31: Cone checker | I31: 2*3 | J31: 6 | K31: =J31 -> 6 | L31: 0 | M31: 2 | N31: 2 | O31: 2 | P31: 0
A32: Vapi | B32: Spinning | C32: TFO | D32: 10 | E32: Cone tipping | I32: 1*3 | J32: 3 | K32: =J32 -> 3 | L32: 0 | M32: 1 | N32: 1 | O32: 1 | P32: 0
A33: Vapi | B33: Spinning | C33: TFO | D33: 11 | E33: Fork lift opt | I33: 1*1 | J33: 1 | K33: =J33 -> 1 | L33: 1 | M33: 0 | N33: 0 | O33: 0 | P33: 0
A34: Vapi | B34: Spinning | C34: TFO | D34: 12 | E34: Packer | I34: 4*3 | J34: 12 | K34: =J34 -> 12 | L34: 0 | M34: 4 | N34: 4 | O34: 4 | P34: 0
A35: Vapi | B35: Spinning | C35: TFO | D35: 13 | E35: Packing Jobber | F35: Jobber | I35: 0*3 | J35: 0 | K35: =J35 -> 0 | L35: 0 | M35: 0 | N35: 0 | O35: 0 | P35: 0
A36: Vapi | B36: Spinning | C36: TFO | D36: 15 | E36: DEO | F36: DEO | I36: 1*1 | J36: 1 | K36: =J36 -> 1 | L36: 1 | M36: 0 | N36: 0 | O36: 0 | P36: 0
A37: Vapi | B37: Spinning | C37: TFO | D37: 16 | E37: House Keeper | F37: Contractors | I37: 2*3 | J37: 6 | K37: =J37 -> 6 | L37: 0 | M37: 2 | N37: 2 | O37: 2 | P37: 0
